[2025-10-04T23:23:56.019+0000] {taskinstance.py:1956} INFO - Dependencies all met for dep_context=non-requeueable deps ti=<TaskInstance: ingest_data_dag.ingest_orders_data manual__2025-10-04T23:17:44.635799+00:00 [queued]>
[2025-10-04T23:23:56.031+0000] {taskinstance.py:1956} INFO - Dependencies all met for dep_context=requeueable deps ti=<TaskInstance: ingest_data_dag.ingest_orders_data manual__2025-10-04T23:17:44.635799+00:00 [queued]>
[2025-10-04T23:23:56.032+0000] {taskinstance.py:2170} INFO - Starting attempt 2 of 2
[2025-10-04T23:23:56.050+0000] {taskinstance.py:2191} INFO - Executing <Task(S3ToSqlOperator): ingest_orders_data> on 2025-10-04 23:17:44.635799+00:00
[2025-10-04T23:23:56.058+0000] {standard_task_runner.py:60} INFO - Started process 2262 to run task
[2025-10-04T23:23:56.066+0000] {standard_task_runner.py:87} INFO - Running: ['***', 'tasks', 'run', 'ingest_data_dag', 'ingest_orders_data', 'manual__2025-10-04T23:17:44.635799+00:00', '--job-id', '14', '--raw', '--subdir', 'DAGS_FOLDER/dag_ingest_data.py', '--cfg-path', '/tmp/tmp0ysd_1pf']
[2025-10-04T23:23:56.071+0000] {standard_task_runner.py:88} INFO - Job 14: Subtask ingest_orders_data
[2025-10-04T23:23:56.172+0000] {task_command.py:423} INFO - Running <TaskInstance: ingest_data_dag.ingest_orders_data manual__2025-10-04T23:17:44.635799+00:00 [running]> on host ff034d7c1964
[2025-10-04T23:23:56.267+0000] {taskinstance.py:2480} INFO - Exporting env vars: AIRFLOW_CTX_DAG_OWNER='***' AIRFLOW_CTX_DAG_ID='ingest_data_dag' AIRFLOW_CTX_TASK_ID='ingest_orders_data' AIRFLOW_CTX_EXECUTION_DATE='2025-10-04T23:17:44.635799+00:00' AIRFLOW_CTX_TRY_NUMBER='2' AIRFLOW_CTX_DAG_RUN_ID='manual__2025-10-04T23:17:44.635799+00:00'
[2025-10-04T23:23:56.268+0000] {s3_to_sql.py:105} INFO - Loading orders.csv to SQL table "staging"."orders"...
[2025-10-04T23:23:56.280+0000] {base.py:83} INFO - Using connection ID 'minio_s3' for task execution.
[2025-10-04T23:23:56.281+0000] {connection_wrapper.py:378} INFO - AWS Connection (conn_id='minio_s3', conn_type='aws') credentials retrieved from login and password.
[2025-10-04T23:23:56.603+0000] {base.py:83} INFO - Using connection ID 'postgres_warehouse' for task execution.
[2025-10-04T23:23:56.626+0000] {base.py:83} INFO - Using connection ID 'postgres_warehouse' for task execution.
[2025-10-04T23:23:56.632+0000] {taskinstance.py:2698} ERROR - Task failed with exception
Traceback (most recent call last):
  File "/home/airflow/.local/lib/python3.8/site-packages/airflow/models/taskinstance.py", line 433, in _execute_task
    result = execute_callable(context=context, **execute_callable_kwargs)
  File "/home/airflow/.local/lib/python3.8/site-packages/airflow/providers/amazon/aws/transfers/s3_to_sql.py", line 115, in execute
    self.db_hook.insert_rows(
  File "/home/airflow/.local/lib/python3.8/site-packages/airflow/providers/common/sql/hooks/sql.py", line 541, in insert_rows
    cur.execute(sql, values)
psycopg2.errors.UndefinedTable: relation "staging.orders" does not exist
LINE 1: INSERT INTO "staging"."orders"  VALUES ('1e724ddb-3112-468e-...
                    ^

[2025-10-04T23:23:56.654+0000] {taskinstance.py:1138} INFO - Marking task as FAILED. dag_id=ingest_data_dag, task_id=ingest_orders_data, execution_date=20251004T231744, start_date=20251004T232356, end_date=20251004T232356
[2025-10-04T23:23:56.670+0000] {standard_task_runner.py:107} ERROR - Failed to execute job 14 for task ingest_orders_data (relation "staging.orders" does not exist
LINE 1: INSERT INTO "staging"."orders"  VALUES ('1e724ddb-3112-468e-...
                    ^
; 2262)
[2025-10-04T23:23:56.723+0000] {local_task_job_runner.py:234} INFO - Task exited with return code 1
[2025-10-04T23:23:56.742+0000] {taskinstance.py:3280} INFO - 0 downstream tasks scheduled from follow-on schedule check
