[2025-10-04T23:28:42.163+0000] {taskinstance.py:1956} INFO - Dependencies all met for dep_context=non-requeueable deps ti=<TaskInstance: ingest_data_dag.ingest_tickets_data manual__2025-10-04T23:17:44.635799+00:00 [queued]>
[2025-10-04T23:28:42.173+0000] {taskinstance.py:1956} INFO - Dependencies all met for dep_context=requeueable deps ti=<TaskInstance: ingest_data_dag.ingest_tickets_data manual__2025-10-04T23:17:44.635799+00:00 [queued]>
[2025-10-04T23:28:42.173+0000] {taskinstance.py:2170} INFO - Starting attempt 3 of 3
[2025-10-04T23:28:42.191+0000] {taskinstance.py:2191} INFO - Executing <Task(S3ToSqlOperator): ingest_tickets_data> on 2025-10-04 23:17:44.635799+00:00
[2025-10-04T23:28:42.235+0000] {standard_task_runner.py:60} INFO - Started process 2474 to run task
[2025-10-04T23:28:42.240+0000] {standard_task_runner.py:87} INFO - Running: ['***', 'tasks', 'run', 'ingest_data_dag', 'ingest_tickets_data', 'manual__2025-10-04T23:17:44.635799+00:00', '--job-id', '20', '--raw', '--subdir', 'DAGS_FOLDER/dag_ingest_data.py', '--cfg-path', '/tmp/tmp3g7zsak5']
[2025-10-04T23:28:42.242+0000] {standard_task_runner.py:88} INFO - Job 20: Subtask ingest_tickets_data
[2025-10-04T23:28:42.306+0000] {task_command.py:423} INFO - Running <TaskInstance: ingest_data_dag.ingest_tickets_data manual__2025-10-04T23:17:44.635799+00:00 [running]> on host ff034d7c1964
[2025-10-04T23:28:42.423+0000] {taskinstance.py:2480} INFO - Exporting env vars: AIRFLOW_CTX_DAG_OWNER='***' AIRFLOW_CTX_DAG_ID='ingest_data_dag' AIRFLOW_CTX_TASK_ID='ingest_tickets_data' AIRFLOW_CTX_EXECUTION_DATE='2025-10-04T23:17:44.635799+00:00' AIRFLOW_CTX_TRY_NUMBER='3' AIRFLOW_CTX_DAG_RUN_ID='manual__2025-10-04T23:17:44.635799+00:00'
[2025-10-04T23:28:42.425+0000] {s3_to_sql.py:105} INFO - Loading support_tickets.csv to SQL table "staging"."tickets"...
[2025-10-04T23:28:42.433+0000] {base_aws.py:581} WARNING - Unable to find AWS Connection ID 'minio_s_3', switching to empty.
[2025-10-04T23:28:42.435+0000] {base_aws.py:161} INFO - No connection ID provided. Fallback on boto3 credential strategy (region_name=None). See: https://boto3.amazonaws.com/v1/documentation/api/latest/guide/configuration.html
[2025-10-04T23:28:42.682+0000] {taskinstance.py:2698} ERROR - Task failed with exception
Traceback (most recent call last):
  File "/home/airflow/.local/lib/python3.8/site-packages/airflow/models/taskinstance.py", line 433, in _execute_task
    result = execute_callable(context=context, **execute_callable_kwargs)
  File "/home/airflow/.local/lib/python3.8/site-packages/airflow/providers/amazon/aws/transfers/s3_to_sql.py", line 108, in execute
    s3_obj = s3_hook.get_key(key=self.s3_key, bucket_name=self.s3_bucket)
  File "/home/airflow/.local/lib/python3.8/site-packages/airflow/providers/amazon/aws/hooks/s3.py", line 137, in wrapper
    return func(*bound_args.args, **bound_args.kwargs)
  File "/home/airflow/.local/lib/python3.8/site-packages/airflow/providers/amazon/aws/hooks/s3.py", line 91, in wrapper
    return func(*bound_args.args, **bound_args.kwargs)
  File "/home/airflow/.local/lib/python3.8/site-packages/airflow/providers/amazon/aws/hooks/s3.py", line 940, in get_key
    obj.load(**sanitize_extra_args())
  File "/home/airflow/.local/lib/python3.8/site-packages/boto3/resources/factory.py", line 565, in do_action
    response = action(self, *args, **kwargs)
  File "/home/airflow/.local/lib/python3.8/site-packages/boto3/resources/action.py", line 88, in __call__
    response = getattr(parent.meta.client, operation_name)(*args, **params)
  File "/home/airflow/.local/lib/python3.8/site-packages/botocore/client.py", line 553, in _api_call
    return self._make_api_call(operation_name, kwargs)
  File "/home/airflow/.local/lib/python3.8/site-packages/botocore/client.py", line 989, in _make_api_call
    http, parsed_response = self._make_request(
  File "/home/airflow/.local/lib/python3.8/site-packages/botocore/client.py", line 1015, in _make_request
    return self._endpoint.make_request(operation_model, request_dict)
  File "/home/airflow/.local/lib/python3.8/site-packages/botocore/endpoint.py", line 119, in make_request
    return self._send_request(request_dict, operation_model)
  File "/home/airflow/.local/lib/python3.8/site-packages/botocore/endpoint.py", line 198, in _send_request
    request = self.create_request(request_dict, operation_model)
  File "/home/airflow/.local/lib/python3.8/site-packages/botocore/endpoint.py", line 134, in create_request
    self._event_emitter.emit(
  File "/home/airflow/.local/lib/python3.8/site-packages/botocore/hooks.py", line 412, in emit
    return self._emitter.emit(aliased_event_name, **kwargs)
  File "/home/airflow/.local/lib/python3.8/site-packages/botocore/hooks.py", line 256, in emit
    return self._emit(event_name, kwargs)
  File "/home/airflow/.local/lib/python3.8/site-packages/botocore/hooks.py", line 239, in _emit
    response = handler(**kwargs)
  File "/home/airflow/.local/lib/python3.8/site-packages/botocore/signers.py", line 105, in handler
    return self.sign(operation_name, request)
  File "/home/airflow/.local/lib/python3.8/site-packages/botocore/signers.py", line 195, in sign
    auth.add_auth(request)
  File "/home/airflow/.local/lib/python3.8/site-packages/botocore/auth.py", line 418, in add_auth
    raise NoCredentialsError()
botocore.exceptions.NoCredentialsError: Unable to locate credentials
[2025-10-04T23:28:42.693+0000] {taskinstance.py:1138} INFO - Marking task as FAILED. dag_id=ingest_data_dag, task_id=ingest_tickets_data, execution_date=20251004T231744, start_date=20251004T232842, end_date=20251004T232842
[2025-10-04T23:28:42.706+0000] {standard_task_runner.py:107} ERROR - Failed to execute job 20 for task ingest_tickets_data (Unable to locate credentials; 2474)
[2025-10-04T23:28:42.734+0000] {local_task_job_runner.py:234} INFO - Task exited with return code 1
[2025-10-04T23:28:42.749+0000] {taskinstance.py:3280} INFO - 0 downstream tasks scheduled from follow-on schedule check
