[2025-10-04T23:06:56.086+0000] {taskinstance.py:1956} INFO - Dependencies all met for dep_context=non-requeueable deps ti=<TaskInstance: ingest_data_dag.ingest_orders_data manual__2025-10-04T23:06:49.926285+00:00 [queued]>
[2025-10-04T23:06:56.104+0000] {taskinstance.py:1956} INFO - Dependencies all met for dep_context=requeueable deps ti=<TaskInstance: ingest_data_dag.ingest_orders_data manual__2025-10-04T23:06:49.926285+00:00 [queued]>
[2025-10-04T23:06:56.105+0000] {taskinstance.py:2170} INFO - Starting attempt 1 of 1
[2025-10-04T23:06:56.129+0000] {taskinstance.py:2191} INFO - Executing <Task(S3ToSqlOperator): ingest_orders_data> on 2025-10-04 23:06:49.926285+00:00
[2025-10-04T23:06:56.139+0000] {standard_task_runner.py:60} INFO - Started process 1564 to run task
[2025-10-04T23:06:56.148+0000] {standard_task_runner.py:87} INFO - Running: ['***', 'tasks', 'run', 'ingest_data_dag', 'ingest_orders_data', 'manual__2025-10-04T23:06:49.926285+00:00', '--job-id', '3', '--raw', '--subdir', 'DAGS_FOLDER/dag_ingest_data.py', '--cfg-path', '/tmp/tmplwei2p45']
[2025-10-04T23:06:56.155+0000] {standard_task_runner.py:88} INFO - Job 3: Subtask ingest_orders_data
[2025-10-04T23:06:56.279+0000] {task_command.py:423} INFO - Running <TaskInstance: ingest_data_dag.ingest_orders_data manual__2025-10-04T23:06:49.926285+00:00 [running]> on host ff034d7c1964
[2025-10-04T23:06:56.539+0000] {taskinstance.py:2480} INFO - Exporting env vars: AIRFLOW_CTX_DAG_OWNER='***' AIRFLOW_CTX_DAG_ID='ingest_data_dag' AIRFLOW_CTX_TASK_ID='ingest_orders_data' AIRFLOW_CTX_EXECUTION_DATE='2025-10-04T23:06:49.926285+00:00' AIRFLOW_CTX_TRY_NUMBER='1' AIRFLOW_CTX_DAG_RUN_ID='manual__2025-10-04T23:06:49.926285+00:00'
[2025-10-04T23:06:56.547+0000] {s3_to_sql.py:105} INFO - Loading orders.csv to SQL table "staging"."orders"...
[2025-10-04T23:06:56.601+0000] {base.py:83} INFO - Using connection ID 'minio_s3' for task execution.
[2025-10-04T23:06:56.604+0000] {connection_wrapper.py:378} INFO - AWS Connection (conn_id='minio_s3', conn_type='aws') credentials retrieved from login and password.
[2025-10-04T23:06:58.959+0000] {taskinstance.py:2698} ERROR - Task failed with exception
Traceback (most recent call last):
  File "/home/airflow/.local/lib/python3.8/site-packages/airflow/models/taskinstance.py", line 433, in _execute_task
    result = execute_callable(context=context, **execute_callable_kwargs)
  File "/home/airflow/.local/lib/python3.8/site-packages/airflow/providers/amazon/aws/transfers/s3_to_sql.py", line 108, in execute
    s3_obj = s3_hook.get_key(key=self.s3_key, bucket_name=self.s3_bucket)
  File "/home/airflow/.local/lib/python3.8/site-packages/airflow/providers/amazon/aws/hooks/s3.py", line 137, in wrapper
    return func(*bound_args.args, **bound_args.kwargs)
  File "/home/airflow/.local/lib/python3.8/site-packages/airflow/providers/amazon/aws/hooks/s3.py", line 91, in wrapper
    return func(*bound_args.args, **bound_args.kwargs)
  File "/home/airflow/.local/lib/python3.8/site-packages/airflow/providers/amazon/aws/hooks/s3.py", line 940, in get_key
    obj.load(**sanitize_extra_args())
  File "/home/airflow/.local/lib/python3.8/site-packages/boto3/resources/factory.py", line 565, in do_action
    response = action(self, *args, **kwargs)
  File "/home/airflow/.local/lib/python3.8/site-packages/boto3/resources/action.py", line 88, in __call__
    response = getattr(parent.meta.client, operation_name)(*args, **params)
  File "/home/airflow/.local/lib/python3.8/site-packages/botocore/client.py", line 553, in _api_call
    return self._make_api_call(operation_name, kwargs)
  File "/home/airflow/.local/lib/python3.8/site-packages/botocore/client.py", line 1009, in _make_api_call
    raise error_class(parsed_response, operation_name)
botocore.exceptions.ClientError: An error occurred (404) when calling the HeadObject operation: Not Found
[2025-10-04T23:06:59.002+0000] {taskinstance.py:1138} INFO - Marking task as FAILED. dag_id=ingest_data_dag, task_id=ingest_orders_data, execution_date=20251004T230649, start_date=20251004T230656, end_date=20251004T230659
[2025-10-04T23:06:59.059+0000] {standard_task_runner.py:107} ERROR - Failed to execute job 3 for task ingest_orders_data (An error occurred (404) when calling the HeadObject operation: Not Found; 1564)
[2025-10-04T23:06:59.150+0000] {local_task_job_runner.py:234} INFO - Task exited with return code 1
[2025-10-04T23:06:59.197+0000] {taskinstance.py:3280} INFO - 0 downstream tasks scheduled from follow-on schedule check
